<?xml version="1.0" encoding="UTF-8"?>
<!-- Generated by org.testng.reporters.JUnitXMLReporter -->
<testsuite ignored="0" hostname="5nroor063" failures="1" tests="2" name="test" time="44.847" errors="0" timestamp="2024-07-01T20:38:53 OESZ">
  <testcase classname="tests.ContactFormTest" name="sendValidMessage" time="10.766"/>
  <testcase classname="tests.ContactFormTest" name="sendInvalidMessage" time="10.314">
    <failure type="java.lang.AssertionError" message="expected [Thank you for your message. It has been sent.] but found [One or more fields have an error. Please check and try again.]">
      <![CDATA[java.lang.AssertionError: expected [Thank you for your message. It has been sent.] but found [One or more fields have an error. Please check and try again.]
at tests.ContactFormTest.sendInvalidMessage(ContactFormTest.java:42)
at java.base/java.util.ArrayList.forEach(ArrayList.java:1511)
... Removed 33 stack frames]]>
    </failure>
  </testcase> <!-- sendInvalidMessage -->
</testsuite> <!-- test -->
